[2022-07-22 05:42:54,061] {taskinstance.py:1179} INFO - Dependencies all met for <TaskInstance: workflow.create_table scheduled__2021-11-22T00:00:00+00:00 [queued]>
[2022-07-22 05:42:54,085] {taskinstance.py:1179} INFO - Dependencies all met for <TaskInstance: workflow.create_table scheduled__2021-11-22T00:00:00+00:00 [queued]>
[2022-07-22 05:42:54,099] {taskinstance.py:1376} INFO - 
--------------------------------------------------------------------------------
[2022-07-22 05:42:54,103] {taskinstance.py:1377} INFO - Starting attempt 1 of 1
[2022-07-22 05:42:54,105] {taskinstance.py:1378} INFO - 
--------------------------------------------------------------------------------
[2022-07-22 05:42:54,141] {taskinstance.py:1397} INFO - Executing <Task(MySqlOperator): create_table> on 2021-11-22 00:00:00+00:00
[2022-07-22 05:42:54,152] {standard_task_runner.py:52} INFO - Started process 2253 to run task
[2022-07-22 05:42:54,175] {standard_task_runner.py:79} INFO - Running: ['***', 'tasks', 'run', 'workflow', 'create_table', 'scheduled__2021-11-22T00:00:00+00:00', '--job-id', '266', '--raw', '--subdir', 'DAGS_FOLDER/test.py', '--cfg-path', '/tmp/tmp_x6sm_p2', '--error-file', '/tmp/tmpv5xa_qst']
[2022-07-22 05:42:54,178] {standard_task_runner.py:80} INFO - Job 266: Subtask create_table
[2022-07-22 05:42:54,445] {task_command.py:371} INFO - Running <TaskInstance: workflow.create_table scheduled__2021-11-22T00:00:00+00:00 [running]> on host cdbfdeb58988
[2022-07-22 05:42:54,991] {taskinstance.py:1591} INFO - Exporting the following env vars:
AIRFLOW_CTX_DAG_OWNER=***
AIRFLOW_CTX_DAG_ID=workflow
AIRFLOW_CTX_TASK_ID=create_table
AIRFLOW_CTX_EXECUTION_DATE=2021-11-22T00:00:00+00:00
AIRFLOW_CTX_TRY_NUMBER=1
AIRFLOW_CTX_DAG_RUN_ID=scheduled__2021-11-22T00:00:00+00:00
[2022-07-22 05:42:54,993] {mysql.py:82} INFO - Executing: CREATE DATABASE FUCK
[2022-07-22 05:42:55,016] {base.py:68} INFO - Using connection ID 'mysql_db' for task execution.
[2022-07-22 05:42:55,019] {taskinstance.py:1909} ERROR - Task failed with exception
Traceback (most recent call last):
  File "/home/airflow/.local/lib/python3.7/site-packages/airflow/providers/mysql/operators/mysql.py", line 84, in execute
    hook.run(self.sql, autocommit=self.autocommit, parameters=self.parameters)
  File "/home/airflow/.local/lib/python3.7/site-packages/airflow/hooks/dbapi.py", line 204, in run
    with closing(self.get_conn()) as conn:
  File "/home/airflow/.local/lib/python3.7/site-packages/airflow/providers/mysql/hooks/mysql.py", line 163, in get_conn
    import MySQLdb
ModuleNotFoundError: No module named 'MySQLdb'
[2022-07-22 05:42:55,054] {taskinstance.py:1420} INFO - Marking task as FAILED. dag_id=workflow, task_id=create_table, execution_date=20211122T000000, start_date=20220722T054254, end_date=20220722T054255
[2022-07-22 05:42:55,097] {standard_task_runner.py:97} ERROR - Failed to execute job 266 for task create_table (No module named 'MySQLdb'; 2253)
[2022-07-22 05:42:55,189] {local_task_job.py:156} INFO - Task exited with return code 1
[2022-07-22 05:42:55,270] {local_task_job.py:273} INFO - 0 downstream tasks scheduled from follow-on schedule check
