[2022-07-22 05:41:35,552] {taskinstance.py:1179} INFO - Dependencies all met for <TaskInstance: workflow.create_table scheduled__2021-07-16T00:00:00+00:00 [queued]>
[2022-07-22 05:41:35,591] {taskinstance.py:1179} INFO - Dependencies all met for <TaskInstance: workflow.create_table scheduled__2021-07-16T00:00:00+00:00 [queued]>
[2022-07-22 05:41:35,591] {taskinstance.py:1376} INFO - 
--------------------------------------------------------------------------------
[2022-07-22 05:41:35,594] {taskinstance.py:1377} INFO - Starting attempt 1 of 1
[2022-07-22 05:41:35,595] {taskinstance.py:1378} INFO - 
--------------------------------------------------------------------------------
[2022-07-22 05:41:35,643] {taskinstance.py:1397} INFO - Executing <Task(MySqlOperator): create_table> on 2021-07-16 00:00:00+00:00
[2022-07-22 05:41:35,686] {standard_task_runner.py:52} INFO - Started process 1932 to run task
[2022-07-22 05:41:35,709] {standard_task_runner.py:79} INFO - Running: ['***', 'tasks', 'run', 'workflow', 'create_table', 'scheduled__2021-07-16T00:00:00+00:00', '--job-id', '137', '--raw', '--subdir', 'DAGS_FOLDER/test.py', '--cfg-path', '/tmp/tmphib8thwm', '--error-file', '/tmp/tmpg75ryqjv']
[2022-07-22 05:41:35,716] {standard_task_runner.py:80} INFO - Job 137: Subtask create_table
[2022-07-22 05:41:35,921] {task_command.py:371} INFO - Running <TaskInstance: workflow.create_table scheduled__2021-07-16T00:00:00+00:00 [running]> on host cdbfdeb58988
[2022-07-22 05:41:36,120] {taskinstance.py:1591} INFO - Exporting the following env vars:
AIRFLOW_CTX_DAG_OWNER=***
AIRFLOW_CTX_DAG_ID=workflow
AIRFLOW_CTX_TASK_ID=create_table
AIRFLOW_CTX_EXECUTION_DATE=2021-07-16T00:00:00+00:00
AIRFLOW_CTX_TRY_NUMBER=1
AIRFLOW_CTX_DAG_RUN_ID=scheduled__2021-07-16T00:00:00+00:00
[2022-07-22 05:41:36,123] {mysql.py:82} INFO - Executing: CREATE DATABASE FUCK
[2022-07-22 05:41:36,142] {base.py:68} INFO - Using connection ID 'mysql_db' for task execution.
[2022-07-22 05:41:36,145] {taskinstance.py:1909} ERROR - Task failed with exception
Traceback (most recent call last):
  File "/home/airflow/.local/lib/python3.7/site-packages/airflow/providers/mysql/operators/mysql.py", line 84, in execute
    hook.run(self.sql, autocommit=self.autocommit, parameters=self.parameters)
  File "/home/airflow/.local/lib/python3.7/site-packages/airflow/hooks/dbapi.py", line 204, in run
    with closing(self.get_conn()) as conn:
  File "/home/airflow/.local/lib/python3.7/site-packages/airflow/providers/mysql/hooks/mysql.py", line 163, in get_conn
    import MySQLdb
ModuleNotFoundError: No module named 'MySQLdb'
[2022-07-22 05:41:36,166] {taskinstance.py:1420} INFO - Marking task as FAILED. dag_id=workflow, task_id=create_table, execution_date=20210716T000000, start_date=20220722T054135, end_date=20220722T054136
[2022-07-22 05:41:36,181] {standard_task_runner.py:97} ERROR - Failed to execute job 137 for task create_table (No module named 'MySQLdb'; 1932)
[2022-07-22 05:41:36,240] {local_task_job.py:156} INFO - Task exited with return code 1
[2022-07-22 05:41:36,296] {local_task_job.py:273} INFO - 0 downstream tasks scheduled from follow-on schedule check
