[2022-07-22 05:43:22,405] {taskinstance.py:1179} INFO - Dependencies all met for <TaskInstance: workflow.create_table scheduled__2022-01-05T00:00:00+00:00 [queued]>
[2022-07-22 05:43:22,447] {taskinstance.py:1179} INFO - Dependencies all met for <TaskInstance: workflow.create_table scheduled__2022-01-05T00:00:00+00:00 [queued]>
[2022-07-22 05:43:22,449] {taskinstance.py:1376} INFO - 
--------------------------------------------------------------------------------
[2022-07-22 05:43:22,450] {taskinstance.py:1377} INFO - Starting attempt 1 of 1
[2022-07-22 05:43:22,456] {taskinstance.py:1378} INFO - 
--------------------------------------------------------------------------------
[2022-07-22 05:43:22,508] {taskinstance.py:1397} INFO - Executing <Task(MySqlOperator): create_table> on 2022-01-05 00:00:00+00:00
[2022-07-22 05:43:22,528] {standard_task_runner.py:52} INFO - Started process 2359 to run task
[2022-07-22 05:43:22,549] {standard_task_runner.py:79} INFO - Running: ['***', 'tasks', 'run', 'workflow', 'create_table', 'scheduled__2022-01-05T00:00:00+00:00', '--job-id', '310', '--raw', '--subdir', 'DAGS_FOLDER/test.py', '--cfg-path', '/tmp/tmpkepdvdxb', '--error-file', '/tmp/tmpz04ie_a_']
[2022-07-22 05:43:22,553] {standard_task_runner.py:80} INFO - Job 310: Subtask create_table
[2022-07-22 05:43:22,724] {task_command.py:371} INFO - Running <TaskInstance: workflow.create_table scheduled__2022-01-05T00:00:00+00:00 [running]> on host cdbfdeb58988
[2022-07-22 05:43:22,895] {taskinstance.py:1591} INFO - Exporting the following env vars:
AIRFLOW_CTX_DAG_OWNER=***
AIRFLOW_CTX_DAG_ID=workflow
AIRFLOW_CTX_TASK_ID=create_table
AIRFLOW_CTX_EXECUTION_DATE=2022-01-05T00:00:00+00:00
AIRFLOW_CTX_TRY_NUMBER=1
AIRFLOW_CTX_DAG_RUN_ID=scheduled__2022-01-05T00:00:00+00:00
[2022-07-22 05:43:22,898] {mysql.py:82} INFO - Executing: CREATE DATABASE FUCK
[2022-07-22 05:43:22,939] {base.py:68} INFO - Using connection ID 'mysql_db' for task execution.
[2022-07-22 05:43:22,942] {taskinstance.py:1909} ERROR - Task failed with exception
Traceback (most recent call last):
  File "/home/airflow/.local/lib/python3.7/site-packages/airflow/providers/mysql/operators/mysql.py", line 84, in execute
    hook.run(self.sql, autocommit=self.autocommit, parameters=self.parameters)
  File "/home/airflow/.local/lib/python3.7/site-packages/airflow/hooks/dbapi.py", line 204, in run
    with closing(self.get_conn()) as conn:
  File "/home/airflow/.local/lib/python3.7/site-packages/airflow/providers/mysql/hooks/mysql.py", line 163, in get_conn
    import MySQLdb
ModuleNotFoundError: No module named 'MySQLdb'
[2022-07-22 05:43:22,961] {taskinstance.py:1420} INFO - Marking task as FAILED. dag_id=workflow, task_id=create_table, execution_date=20220105T000000, start_date=20220722T054322, end_date=20220722T054322
[2022-07-22 05:43:22,978] {standard_task_runner.py:97} ERROR - Failed to execute job 310 for task create_table (No module named 'MySQLdb'; 2359)
[2022-07-22 05:43:23,004] {local_task_job.py:156} INFO - Task exited with return code 1
[2022-07-22 05:43:23,041] {local_task_job.py:273} INFO - 0 downstream tasks scheduled from follow-on schedule check
