[2022-07-22 05:42:28,950] {taskinstance.py:1179} INFO - Dependencies all met for <TaskInstance: workflow.create_table scheduled__2021-10-13T00:00:00+00:00 [queued]>
[2022-07-22 05:42:28,986] {taskinstance.py:1179} INFO - Dependencies all met for <TaskInstance: workflow.create_table scheduled__2021-10-13T00:00:00+00:00 [queued]>
[2022-07-22 05:42:28,989] {taskinstance.py:1376} INFO - 
--------------------------------------------------------------------------------
[2022-07-22 05:42:28,991] {taskinstance.py:1377} INFO - Starting attempt 1 of 1
[2022-07-22 05:42:28,992] {taskinstance.py:1378} INFO - 
--------------------------------------------------------------------------------
[2022-07-22 05:42:29,012] {taskinstance.py:1397} INFO - Executing <Task(MySqlOperator): create_table> on 2021-10-13 00:00:00+00:00
[2022-07-22 05:42:29,026] {standard_task_runner.py:52} INFO - Started process 2154 to run task
[2022-07-22 05:42:29,050] {standard_task_runner.py:79} INFO - Running: ['***', 'tasks', 'run', 'workflow', 'create_table', 'scheduled__2021-10-13T00:00:00+00:00', '--job-id', '226', '--raw', '--subdir', 'DAGS_FOLDER/test.py', '--cfg-path', '/tmp/tmpjp8r06py', '--error-file', '/tmp/tmpp46pqh40']
[2022-07-22 05:42:29,062] {standard_task_runner.py:80} INFO - Job 226: Subtask create_table
[2022-07-22 05:42:29,281] {task_command.py:371} INFO - Running <TaskInstance: workflow.create_table scheduled__2021-10-13T00:00:00+00:00 [running]> on host cdbfdeb58988
[2022-07-22 05:42:29,425] {taskinstance.py:1591} INFO - Exporting the following env vars:
AIRFLOW_CTX_DAG_OWNER=***
AIRFLOW_CTX_DAG_ID=workflow
AIRFLOW_CTX_TASK_ID=create_table
AIRFLOW_CTX_EXECUTION_DATE=2021-10-13T00:00:00+00:00
AIRFLOW_CTX_TRY_NUMBER=1
AIRFLOW_CTX_DAG_RUN_ID=scheduled__2021-10-13T00:00:00+00:00
[2022-07-22 05:42:29,429] {mysql.py:82} INFO - Executing: CREATE DATABASE FUCK
[2022-07-22 05:42:29,456] {base.py:68} INFO - Using connection ID 'mysql_db' for task execution.
[2022-07-22 05:42:29,460] {taskinstance.py:1909} ERROR - Task failed with exception
Traceback (most recent call last):
  File "/home/airflow/.local/lib/python3.7/site-packages/airflow/providers/mysql/operators/mysql.py", line 84, in execute
    hook.run(self.sql, autocommit=self.autocommit, parameters=self.parameters)
  File "/home/airflow/.local/lib/python3.7/site-packages/airflow/hooks/dbapi.py", line 204, in run
    with closing(self.get_conn()) as conn:
  File "/home/airflow/.local/lib/python3.7/site-packages/airflow/providers/mysql/hooks/mysql.py", line 163, in get_conn
    import MySQLdb
ModuleNotFoundError: No module named 'MySQLdb'
[2022-07-22 05:42:29,486] {taskinstance.py:1420} INFO - Marking task as FAILED. dag_id=workflow, task_id=create_table, execution_date=20211013T000000, start_date=20220722T054228, end_date=20220722T054229
[2022-07-22 05:42:29,502] {standard_task_runner.py:97} ERROR - Failed to execute job 226 for task create_table (No module named 'MySQLdb'; 2154)
[2022-07-22 05:42:29,541] {local_task_job.py:156} INFO - Task exited with return code 1
[2022-07-22 05:42:29,599] {local_task_job.py:273} INFO - 0 downstream tasks scheduled from follow-on schedule check
