[2022-07-22 05:42:50,552] {taskinstance.py:1179} INFO - Dependencies all met for <TaskInstance: workflow.create_table scheduled__2021-11-19T00:00:00+00:00 [queued]>
[2022-07-22 05:42:50,575] {taskinstance.py:1179} INFO - Dependencies all met for <TaskInstance: workflow.create_table scheduled__2021-11-19T00:00:00+00:00 [queued]>
[2022-07-22 05:42:50,578] {taskinstance.py:1376} INFO - 
--------------------------------------------------------------------------------
[2022-07-22 05:42:50,578] {taskinstance.py:1377} INFO - Starting attempt 1 of 1
[2022-07-22 05:42:50,579] {taskinstance.py:1378} INFO - 
--------------------------------------------------------------------------------
[2022-07-22 05:42:50,627] {taskinstance.py:1397} INFO - Executing <Task(MySqlOperator): create_table> on 2021-11-19 00:00:00+00:00
[2022-07-22 05:42:50,636] {standard_task_runner.py:52} INFO - Started process 2243 to run task
[2022-07-22 05:42:50,668] {standard_task_runner.py:79} INFO - Running: ['***', 'tasks', 'run', 'workflow', 'create_table', 'scheduled__2021-11-19T00:00:00+00:00', '--job-id', '263', '--raw', '--subdir', 'DAGS_FOLDER/test.py', '--cfg-path', '/tmp/tmp1cfymfdl', '--error-file', '/tmp/tmpwubp28cp']
[2022-07-22 05:42:50,669] {standard_task_runner.py:80} INFO - Job 263: Subtask create_table
[2022-07-22 05:42:50,777] {task_command.py:371} INFO - Running <TaskInstance: workflow.create_table scheduled__2021-11-19T00:00:00+00:00 [running]> on host cdbfdeb58988
[2022-07-22 05:42:50,859] {taskinstance.py:1591} INFO - Exporting the following env vars:
AIRFLOW_CTX_DAG_OWNER=***
AIRFLOW_CTX_DAG_ID=workflow
AIRFLOW_CTX_TASK_ID=create_table
AIRFLOW_CTX_EXECUTION_DATE=2021-11-19T00:00:00+00:00
AIRFLOW_CTX_TRY_NUMBER=1
AIRFLOW_CTX_DAG_RUN_ID=scheduled__2021-11-19T00:00:00+00:00
[2022-07-22 05:42:50,861] {mysql.py:82} INFO - Executing: CREATE DATABASE FUCK
[2022-07-22 05:42:50,876] {base.py:68} INFO - Using connection ID 'mysql_db' for task execution.
[2022-07-22 05:42:50,878] {taskinstance.py:1909} ERROR - Task failed with exception
Traceback (most recent call last):
  File "/home/airflow/.local/lib/python3.7/site-packages/airflow/providers/mysql/operators/mysql.py", line 84, in execute
    hook.run(self.sql, autocommit=self.autocommit, parameters=self.parameters)
  File "/home/airflow/.local/lib/python3.7/site-packages/airflow/hooks/dbapi.py", line 204, in run
    with closing(self.get_conn()) as conn:
  File "/home/airflow/.local/lib/python3.7/site-packages/airflow/providers/mysql/hooks/mysql.py", line 163, in get_conn
    import MySQLdb
ModuleNotFoundError: No module named 'MySQLdb'
[2022-07-22 05:42:50,886] {taskinstance.py:1420} INFO - Marking task as FAILED. dag_id=workflow, task_id=create_table, execution_date=20211119T000000, start_date=20220722T054250, end_date=20220722T054250
[2022-07-22 05:42:50,902] {standard_task_runner.py:97} ERROR - Failed to execute job 263 for task create_table (No module named 'MySQLdb'; 2243)
[2022-07-22 05:42:50,938] {local_task_job.py:156} INFO - Task exited with return code 1
[2022-07-22 05:42:50,969] {local_task_job.py:273} INFO - 0 downstream tasks scheduled from follow-on schedule check
