[2022-07-22 05:41:32,866] {taskinstance.py:1179} INFO - Dependencies all met for <TaskInstance: workflow.create_table scheduled__2021-07-11T00:00:00+00:00 [queued]>
[2022-07-22 05:41:32,902] {taskinstance.py:1179} INFO - Dependencies all met for <TaskInstance: workflow.create_table scheduled__2021-07-11T00:00:00+00:00 [queued]>
[2022-07-22 05:41:32,903] {taskinstance.py:1376} INFO - 
--------------------------------------------------------------------------------
[2022-07-22 05:41:32,904] {taskinstance.py:1377} INFO - Starting attempt 1 of 1
[2022-07-22 05:41:32,904] {taskinstance.py:1378} INFO - 
--------------------------------------------------------------------------------
[2022-07-22 05:41:32,943] {taskinstance.py:1397} INFO - Executing <Task(MySqlOperator): create_table> on 2021-07-11 00:00:00+00:00
[2022-07-22 05:41:32,960] {standard_task_runner.py:52} INFO - Started process 1918 to run task
[2022-07-22 05:41:33,000] {standard_task_runner.py:79} INFO - Running: ['***', 'tasks', 'run', 'workflow', 'create_table', 'scheduled__2021-07-11T00:00:00+00:00', '--job-id', '132', '--raw', '--subdir', 'DAGS_FOLDER/test.py', '--cfg-path', '/tmp/tmp3jpdq99r', '--error-file', '/tmp/tmp9vuw2op1']
[2022-07-22 05:41:33,001] {standard_task_runner.py:80} INFO - Job 132: Subtask create_table
[2022-07-22 05:41:33,097] {task_command.py:371} INFO - Running <TaskInstance: workflow.create_table scheduled__2021-07-11T00:00:00+00:00 [running]> on host cdbfdeb58988
[2022-07-22 05:41:33,194] {taskinstance.py:1591} INFO - Exporting the following env vars:
AIRFLOW_CTX_DAG_OWNER=***
AIRFLOW_CTX_DAG_ID=workflow
AIRFLOW_CTX_TASK_ID=create_table
AIRFLOW_CTX_EXECUTION_DATE=2021-07-11T00:00:00+00:00
AIRFLOW_CTX_TRY_NUMBER=1
AIRFLOW_CTX_DAG_RUN_ID=scheduled__2021-07-11T00:00:00+00:00
[2022-07-22 05:41:33,196] {mysql.py:82} INFO - Executing: CREATE DATABASE FUCK
[2022-07-22 05:41:33,209] {base.py:68} INFO - Using connection ID 'mysql_db' for task execution.
[2022-07-22 05:41:33,213] {taskinstance.py:1909} ERROR - Task failed with exception
Traceback (most recent call last):
  File "/home/airflow/.local/lib/python3.7/site-packages/airflow/providers/mysql/operators/mysql.py", line 84, in execute
    hook.run(self.sql, autocommit=self.autocommit, parameters=self.parameters)
  File "/home/airflow/.local/lib/python3.7/site-packages/airflow/hooks/dbapi.py", line 204, in run
    with closing(self.get_conn()) as conn:
  File "/home/airflow/.local/lib/python3.7/site-packages/airflow/providers/mysql/hooks/mysql.py", line 163, in get_conn
    import MySQLdb
ModuleNotFoundError: No module named 'MySQLdb'
[2022-07-22 05:41:33,221] {taskinstance.py:1420} INFO - Marking task as FAILED. dag_id=workflow, task_id=create_table, execution_date=20210711T000000, start_date=20220722T054132, end_date=20220722T054133
[2022-07-22 05:41:33,240] {standard_task_runner.py:97} ERROR - Failed to execute job 132 for task create_table (No module named 'MySQLdb'; 1918)
[2022-07-22 05:41:33,270] {local_task_job.py:156} INFO - Task exited with return code 1
[2022-07-22 05:41:33,329] {local_task_job.py:273} INFO - 0 downstream tasks scheduled from follow-on schedule check
