[2022-07-22 05:44:01,218] {taskinstance.py:1179} INFO - Dependencies all met for <TaskInstance: workflow.create_table scheduled__2022-03-18T00:00:00+00:00 [queued]>
[2022-07-22 05:44:01,240] {taskinstance.py:1179} INFO - Dependencies all met for <TaskInstance: workflow.create_table scheduled__2022-03-18T00:00:00+00:00 [queued]>
[2022-07-22 05:44:01,241] {taskinstance.py:1376} INFO - 
--------------------------------------------------------------------------------
[2022-07-22 05:44:01,242] {taskinstance.py:1377} INFO - Starting attempt 1 of 1
[2022-07-22 05:44:01,243] {taskinstance.py:1378} INFO - 
--------------------------------------------------------------------------------
[2022-07-22 05:44:01,289] {taskinstance.py:1397} INFO - Executing <Task(MySqlOperator): create_table> on 2022-03-18 00:00:00+00:00
[2022-07-22 05:44:01,320] {standard_task_runner.py:52} INFO - Started process 2537 to run task
[2022-07-22 05:44:01,344] {standard_task_runner.py:79} INFO - Running: ['***', 'tasks', 'run', 'workflow', 'create_table', 'scheduled__2022-03-18T00:00:00+00:00', '--job-id', '382', '--raw', '--subdir', 'DAGS_FOLDER/test.py', '--cfg-path', '/tmp/tmpd8p3po7v', '--error-file', '/tmp/tmp3czyolt4']
[2022-07-22 05:44:01,364] {standard_task_runner.py:80} INFO - Job 382: Subtask create_table
[2022-07-22 05:44:01,590] {task_command.py:371} INFO - Running <TaskInstance: workflow.create_table scheduled__2022-03-18T00:00:00+00:00 [running]> on host cdbfdeb58988
[2022-07-22 05:44:01,749] {taskinstance.py:1591} INFO - Exporting the following env vars:
AIRFLOW_CTX_DAG_OWNER=***
AIRFLOW_CTX_DAG_ID=workflow
AIRFLOW_CTX_TASK_ID=create_table
AIRFLOW_CTX_EXECUTION_DATE=2022-03-18T00:00:00+00:00
AIRFLOW_CTX_TRY_NUMBER=1
AIRFLOW_CTX_DAG_RUN_ID=scheduled__2022-03-18T00:00:00+00:00
[2022-07-22 05:44:01,752] {mysql.py:82} INFO - Executing: CREATE DATABASE FUCK
[2022-07-22 05:44:01,769] {base.py:68} INFO - Using connection ID 'mysql_db' for task execution.
[2022-07-22 05:44:01,771] {taskinstance.py:1909} ERROR - Task failed with exception
Traceback (most recent call last):
  File "/home/airflow/.local/lib/python3.7/site-packages/airflow/providers/mysql/operators/mysql.py", line 84, in execute
    hook.run(self.sql, autocommit=self.autocommit, parameters=self.parameters)
  File "/home/airflow/.local/lib/python3.7/site-packages/airflow/hooks/dbapi.py", line 204, in run
    with closing(self.get_conn()) as conn:
  File "/home/airflow/.local/lib/python3.7/site-packages/airflow/providers/mysql/hooks/mysql.py", line 163, in get_conn
    import MySQLdb
ModuleNotFoundError: No module named 'MySQLdb'
[2022-07-22 05:44:01,781] {taskinstance.py:1420} INFO - Marking task as FAILED. dag_id=workflow, task_id=create_table, execution_date=20220318T000000, start_date=20220722T054401, end_date=20220722T054401
[2022-07-22 05:44:01,817] {standard_task_runner.py:97} ERROR - Failed to execute job 382 for task create_table (No module named 'MySQLdb'; 2537)
[2022-07-22 05:44:01,875] {local_task_job.py:156} INFO - Task exited with return code 1
[2022-07-22 05:44:01,921] {local_task_job.py:273} INFO - 0 downstream tasks scheduled from follow-on schedule check
